Workbook

Sheet Support
F3: Incidents | I3: Service Requests | M3: Enhancements | Q3: Service Improvements
B4: Portfolio | C4: App / Product Name | D4: Owner | E4: Month (2025) | F4: Total Incidents | G4: Number of major incidents (P1 & P2) | H4: Number of Aged Incidents (Over 30 days) | I4: Tasks Received | J4: Open Tasks | K4: Completed Tasks | L4: Aged Tasks (Over 30 days) | M4: Enhancement Requests | N4: Completed Enhancements | O4: Enhancement Backlog | P4: Aged Enhancements in Backlog (Over 30 days) | Q4: Number of improvements | R4: Comment on the improvement
B5: Aviation | C5: Airfeild Automation | D5: Bindu | E5: January | F5: 95 | G5: 0 | H5: 0 | I5: 142 | J5: 0 | K5: 142 | L5: 0
B6: Aviation | C6: Airfeild Automation | D6: Bindu | E6: February | F6: 121 | G6: 0 | H6: 0 | I6: 152 | J6: 7 | K6: 145 | L6: 0
B7: Aviation | C7: CADOPS and RADAR | D7: Bindu | E7: January | F7: 2 | G7: 0 | H7: 0 | I7: 29 | J7: 0 | K7: 29 | L7: 0
B8: Aviation | C8: CADOPS and RADAR | D8: Bindu | E8: February
B9: Aviation | C9: APT | D9: Vedangi | E9: January | F9: 14 | G9: 0 | H9: 0 | I9: 0 | J9: 0 | K9: 0 | L9: 0
B10: Aviation | C10: APT | D10: Vedangi | E10: February | F10: 7 | G10: 0 | H10: 0 | I10: 0 | J10: 0 | K10: 0 | L10: 0
B11: Aviation | C11: GCT | D11: Vedangi | E11: January | F11: 2 | G11: 0 | H11: 0 | I11: 0 | J11: 0 | K11: 0 | L11: 0
B12: Aviation | C12: GCT | D12: Vedangi | E12: February | F12: 1 | G12: 0 | H12: 0 | I12: 3 | J12: 0 | K12: 3 | L12: 0
B13: Aviation | C13: KEVIN/SYSTEM 42 | D13: Vedangi | E13: January | F13: 4 | G13: 0 | H13: 0 | I13: 0 | J13: 0 | K13: 0 | L13: 0 | M13: 1 | N13: 1
B14: Aviation | C14: KEVIN/SYSTEM 42 | D14: Vedangi | E14: February | F14: 4 | G14: 0 | H14: 0 | I14: 0 | J14: 0 | K14: 0 | L14: 0 | M14: 2 | N14: 2
B15: Aviation | C15: Customer DQ | D15: Vedangi | E15: January | F15: 0 | G15: 0 | H15: 0 | I15: 0 | J15: 0 | K15: 0 | L15: 0
B16: Aviation | C16: Customer DQ | D16: Vedangi | E16: February | F16: 0 | G16: 0 | H16: 0 | I16: 0 | J16: 0 | K16: 0 | L16: 0
B17: Aviation | C17: eBilling | D17: Mathew Jacob | E17: January | G17: 0 | H17: 0 | I17: 7 | J17: 0 | K17: 7 | L17: 0
B18: Aviation | C18: eBilling | D18: Mathew Jacob | E18: February | G18: 0 | H18: 0 | I18: 28 | J18: 0 | K18: 28 | L18: 0
B19: Aviation | C19: Semarchy | D19: Bharat Solanki | E19: January | F19: 0 | G19: 0 | H19: 0 | J19: 0 | L19: 0
B20: Aviation | C20: Semarchy | D20: Bharat Solanki | E20: February | F20: 0 | G20: 0 | H20: 0 | J20: 0 | L20: 0
B21: Aviation | C21: Market Intel Platform (MIP) | D21: Vedangi | E21: January | G21: 0 | H21: 0 | I21: 7 | J21: 0 | K21: 7 | L21: 0
B22: Aviation | C22: Market Intel Platform (MIP) | D22: Vedangi | E22: February | G22: 0 | H22: 0 | I22: 28 | J22: 0 | K22: 28 | L22: 0
B23: Aviation | C23: PowerApps | D23: Vedangi | E23: January | F23: 0 | G23: 0 | H23: 0 | J23: 0 | L23: 0
B24: Aviation | C24: PowerApps | D24: Vedangi | E24: February | F24: 0 | G24: 0 | H24: 0 | J24: 0 | L24: 0
B25: Aviation | C25: AA Database | D25: Vedangi | E25: January | G25: 0 | H25: 0 | I25: 7 | J25: 0 | K25: 7 | L25: 0
B26: Aviation | C26: AA Database | D26: Vedangi | E26: February | G26: 0 | H26: 0 | J26: 0 | L26: 0 | M26: 1 | N26: 0
B27: Castrol | C27: GME Document Hub | D27: Vedangi | E27: January | F27: 0 | G27: 0 | H27: 0 | I27: 0 | J27: 0 | K27: 0 | L27: 0 | M27: 1 | N27: 0
B28: Castrol | C28: GME Document Hub | D28: Vedangi | E28: February | F28: 0 | G28: 0 | H28: 0 | I28: 0 | J28: 0 | K28: 0 | L28: 0
B29: Castrol | C29: DRN Portal | D29: Vedangi | E29: January | F29: 50 | G29: 0 | H29: 0 | I29: 7 | J29: 0 | K29: 7 | L29: 0
B30: Castrol | C30: DRN Portal | D30: Vedangi | E30: February | F30: 49 | G30: 0 | H30: 0 | I30: 5 | J30: 0 | K30: 5 | L30: 0
B31: Castrol | C31: Formscape | D31: Vedangi | E31: January | F31: 0 | G31: 0 | H31: 0 | I31: 36 | J31: 0 | K31: 36 | L31: 0
B32: Castrol | C32: Formscape | D32: Vedangi | E32: February | F32: 1 | G32: 0 | H32: 0 | I32: 21 | J32: 0 | K32: 21 | L32: 0
B33: Castrol | C33: Pricing Accelerator | D33: Vedangi | E33: January | F33: 3 | G33: 0 | H33: 0 | I33: 2 | J33: 0 | K33: 2 | L33: 0
B34: Castrol | C34: Pricing Accelerator | D34: Vedangi | E34: February | F34: 4 | G34: 0 | H34: 0 | I34: 0 | J34: 0 | K34: 0 | L34: 0
B35: Castrol | C35: Credit App | D35: Vedangi | E35: January | F35: 0 | G35: 0 | H35: 0 | I35: 0 | J35: 0 | K35: 0 | L35: 0
B36: Castrol | C36: Credit App | D36: Vedangi | E36: February | F36: 0 | G36: 0 | H36: 0 | I36: 0 | J36: 0 | K36: 0 | L36: 0
B37: Castrol | C37: Mira | D37: Vedangi | E37: January | F37: NA | G37: 0 | H37: 0 | I37: NA | J37: 0 | K37: NA | L37: 0 | M37: NA | N37: NA | O37: NA | P37: NA | Q37: NA | R37: NA
B38: Castrol | C38: Mira | D38: Vedangi | E38: February | F38: NA | G38: 0 | H38: 0 | I38: NA | J38: 0 | K38: NA | L38: 0 | M38: NA | N38: NA | O38: NA | P38: NA | Q38: NA | R38: NA
B39: Castrol | C39: Skate | D39: Vedangi | E39: January | F39: 0 | G39: 0 | H39: 0 | I39: 0 | J39: 0 | K39: 0 | L39: 0
B40: Castrol | C40: Skate | D40: Vedangi | E40: February | F40: 0 | G40: 0 | H40: 0 | I40: 0 | J40: 0 | K40: 0 | L40: 0
B41: Castrol | C41: OMSOnline | D41: Vedangi | E41: January | F41: 10 | G41: 0 | H41: 0 | I41: 20 | J41: 0 | K41: 20 | L41: 0 | M41: NA | N41: NA | O41: NA | P41: NA | Q41: NA | R41: NA
B42: Castrol | C42: OMSOnline | D42: Vedangi | E42: February | F42: 2 | G42: 0 | H42: 0 | I42: 19 | J42: 0 | K42: 19 | L42: 0 | M42: NA | N42: NA | O42: NA | P42: NA | Q42: NA | R42: NA
...

Sheet Development
F3: Velocity | H3: Quality | K3: AI based productivity improvements
B4: Portfolio | C4: App / Product Name | D4: Owner | E4: Month (2025) | F4: % of Committed Product Backlog Item (PBI’s) (Ready) vs Delivered (Done) | G4: % of Story Points (SPs / Efforts) planned vs number of stories delivered | H4: Successful CI Changes (%) | I4: Number of Priority 3 and Priority 4 Incidents caused by CI Changes | J4: Automated test coverage (%) | K4: Number of AI based productivity improvement proposals | L4: Number of AI based productivity improvement tests | M4: Number of AI based productivity improvement approved and in flight | N4: Estimated value of productivity improvements ($)
B5: Aviation | C5: Airfeild Automation | D5: Bindu | E5: January | F5: =10/13 -> 0.76923077 | G5: =42/56 -> 0.75 | H5: 1 | I5: 0 | J5: 0.81 | K5: 0 | L5: 0 | M5: 0 | N5: NA
B6: Aviation | C6: Airfeild Automation | D6: Bindu | E6: February | F6: =11/10 -> 1.1 | G6: =72/72 -> 1 | H6: 1 | I6: 0 | J6: 0.855 | K6: 0 | L6: 0 | M6: 0 | N6: NA
B7: Aviation | C7: CADOPS and RADAR | D7: Bindu | E7: January | F7: 1 | G7: NA | H7: 1 | I7: 0 | J7: NA | K7: 0 | L7: 0 | M7: 0 | N7: NA
B8: Aviation | C8: CADOPS and RADAR | D8: Bindu | E8: February | F8: 1 | G8: NA | H8: 1 | I8: 0 | J8: NA | K8: 0 | L8: 0 | M8: 0 | N8: NA
B9: Aviation | C9: APT | D9: Vedangi | E9: January | J9: NA | K9: 0 | L9: 0 | M9: 0 | N9: NA
B10: Aviation | C10: APT | D10: Vedangi | E10: February | F10: 0.84 | G10: 0.1257 | H10: 1 | J10: NA | K10: 0 | L10: 0 | M10: 0 | N10: NA
B11: Aviation | C11: GCT | D11: Vedangi | E11: January | J11: NA | K11: 0 | L11: 0 | M11: 0 | N11: NA
B12: Aviation | C12: GCT | D12: Vedangi | E12: February | H12: 1 | J12: NA | K12: 0 | L12: 0 | M12: 0 | N12: NA
B13: Aviation | C13: KEVIN/SYSTEM 42 | D13: Vedangi | E13: January | J13: NA | K13: 0 | L13: 0 | M13: 0 | N13: NA
B14: Aviation | C14: KEVIN/SYSTEM 42 | D14: Vedangi | E14: February | H14: 1 | J14: NA | K14: 0 | L14: 0 | M14: 0 | N14: NA
B15: Aviation | C15: Customer DQ | D15: Vedangi | E15: January | H15: 1 | J15: NA | K15: 0 | L15: 0 | M15: 0 | N15: NA
B16: Aviation | C16: Customer DQ | D16: Vedangi | E16: February | H16: 1 | J16: NA | K16: 0 | L16: 0 | M16: 0 | N16: NA
B17: Aviation | C17: eBilling | D17: Mathew Jacob | E17: January
B18: Aviation | C18: eBilling | D18: Mathew Jacob | E18: February
B19: Aviation | C19: Semarchy | D19: Bharat Solanki | E19: January
B20: Aviation | C20: Semarchy | D20: Bharat Solanki | E20: February
B21: Aviation | C21: Market Intel Platform (MIP) | D21: Vedangi | E21: January | H21: 1 | J21: NA | K21: 0 | L21: 0 | M21: 0 | N21: NA
B22: Aviation | C22: Market Intel Platform (MIP) | D22: Vedangi | E22: February | H22: 1 | J22: NA | K22: 0 | L22: 0 | M22: 0 | N22: NA
B23: Aviation | C23: PowerApps | D23: Vedangi | E23: January | F23: 0.8 | G23: NA (As of now story points are not aplicable will bring into practice from next sprint) | H23: 1 | I23: Nil | J23: NA | K23: NA | L23: NA | M23: NA | N23: NA
B24: Aviation | C24: PowerApps | D24: Vedangi | E24: February | F24: 0.9 | G24: NA | H24: 1 | I24: Nil | J24: NA | K24: NA | L24: NA | M24: NA | N24: NA
B25: Aviation | C25: AA Database | D25: Vedangi | E25: January | H25: 1 | J25: NA | K25: 0 | L25: 0 | M25: 0 | N25: NA
B26: Aviation | C26: AA Database | D26: Vedangi | E26: February | H26: 1 | J26: NA | K26: 0 | L26: 0 | M26: 0 | N26: NA
B27: Castrol | C27: GME Document Hub | D27: Vedangi | E27: January | H27: 1 | J27: NA | K27: 0 | L27: 0 | M27: 0 | N27: NA
B28: Castrol | C28: GME Document Hub | D28: Vedangi | E28: February | H28: 1 | J28: NA | K28: 0 | L28: 0 | M28: 0 | N28: NA
B29: Castrol | C29: DRN Portal | D29: Vedangi | E29: January | H29: 1 | J29: NA | K29: 0 | L29: 0 | M29: 0 | N29: NA
B30: Castrol | C30: DRN Portal | D30: Vedangi | E30: February | H30: 1 | J30: NA | K30: 0 | L30: 0 | M30: 0 | N30: NA
B31: Castrol | C31: Formscape | D31: Vedangi | E31: January | H31: 1 | J31: NA | K31: 0 | L31: 0 | M31: 0 | N31: NA
B32: Castrol | C32: Formscape | D32: Vedangi | E32: February | H32: 1 | J32: NA | K32: 0 | L32: 0 | M32: 0 | N32: NA
B33: Castrol | C33: Pricing Accelerator | D33: Vedangi | E33: January | H33: 1 | J33: NA | K33: 0 | L33: 0 | M33: 0 | N33: NA
B34: Castrol | C34: Pricing Accelerator | D34: Vedangi | E34: February | H34: 1 | J34: NA | K34: 0 | L34: 0 | M34: 0 | N34: NA
B35: Castrol | C35: Credit App | D35: Vedangi | E35: January | H35: 1 | J35: NA | K35: 0 | L35: 0 | M35: 0 | N35: NA
B36: Castrol | C36: Credit App | D36: Vedangi | E36: February | H36: 1 | J36: NA | K36: 0 | L36: 0 | M36: 0 | N36: NA
B37: Castrol | C37: Mira | E37: January | F37: NA | G37: NA | H37: NA | I37: NA | J37: NA | K37: NA | L37: NA | M37: NA | N37: NA
B38: Castrol | C38: Mira | E38: February | F38: NA | G38: NA | H38: NA | I38: NA | J38: NA | K38: NA | L38: NA | M38: NA | N38: NA
B39: Castrol | C39: Skate | D39: Vedangi | E39: January | H39: 1 | J39: NA | K39: 0 | L39: 0 | M39: 0 | N39: NA
B40: Castrol | C40: Skate | D40: Vedangi | E40: February | H40: 1 | J40: NA | K40: 0 | L40: 0 | M40: 0 | N40: NA
B41: Castrol | C41: OMSOnline | D41: Vedangi | E41: January | H41: 1 | J41: NA | K41: 0 | L41: 0 | M41: 0 | N41: NA
B42: Castrol | C42: OMSOnline | D42: Vedangi | E42: February | H42: 1 | J42: NA | K42: 0 | L42: 0 | M42: 0 | N42: NA
...

Sheet Roll up - Support
D2: Incidents | G2: Service Requests
D3: Total Incidents | E3: Number of major incidents (P1 & P2) | F3: Number of Aged Incidents (Over 30 days) | G3: Tasks Received | H3: Open Tasks | I3: Completed Tasks | J3: Aged Tasks (Over 30 days)
B4: Aviation | C4: January | D4: =SUMIFS(Support!F:F,Support!B:B,'Roll up - Support'!B4,Support!E:E,'Roll up - Support'!C4) -> 117 | E4: =SUMIFS(Support!G:G,Support!B:B,'Roll up - Support'!B4,Support!E:E,'Roll up - Support'!C4) -> 0 | F4: =SUMIFS(Support!H:H,Support!B:B,'Roll up - Support'!B4,Support!E:E,'Roll up - Support'!C4) -> 0 | G4: =SUMIFS(Support!I:I,Support!B:B,'Roll up - Support'!B4,Support!E:E,'Roll up - Support'!C4) -> 192 | H4: =SUMIFS(Support!J:J,Support!B:B,'Roll up - Support'!B4,Support!E:E,'Roll up - Support'!C4) -> 0 | I4: =SUMIFS(Support!K:K,Support!B:B,'Roll up - Support'!B4,Support!E:E,'Roll up - Support'!C4) -> 192 | J4: =SUMIFS(Support!L:L,Support!B:B,'Roll up - Support'!B4,Support!E:E,'Roll up - Support'!C4) -> 0
B5: Aviation | C5: February | D5: =SUMIFS(Support!F:F,Support!B:B,'Roll up - Support'!B5,Support!E:E,'Roll up - Support'!C5) -> 133 | E5: =SUMIFS(Support!G:G,Support!B:B,'Roll up - Support'!B5,Support!E:E,'Roll up - Support'!C5) -> 0 | F5: =SUMIFS(Support!H:H,Support!B:B,'Roll up - Support'!B5,Support!E:E,'Roll up - Support'!C5) -> 0 | G5: =SUMIFS(Support!I:I,Support!B:B,'Roll up - Support'!B5,Support!E:E,'Roll up - Support'!C5) -> 211 | H5: =SUMIFS(Support!J:J,Support!B:B,'Roll up - Support'!B5,Support!E:E,'Roll up - Support'!C5) -> 7 | I5: =SUMIFS(Support!K:K,Support!B:B,'Roll up - Support'!B5,Support!E:E,'Roll up - Support'!C5) -> 204 | J5: =SUMIFS(Support!L:L,Support!B:B,'Roll up - Support'!B5,Support!E:E,'Roll up - Support'!C5) -> 0
B6: Castrol | C6: January | D6: =SUMIFS(Support!F:F,Support!B:B,'Roll up - Support'!B6,Support!E:E,'Roll up - Support'!C6) -> 65 | E6: =SUMIFS(Support!G:G,Support!B:B,'Roll up - Support'!B6,Support!E:E,'Roll up - Support'!C6) -> 0 | F6: =SUMIFS(Support!H:H,Support!B:B,'Roll up - Support'!B6,Support!E:E,'Roll up - Support'!C6) -> 0 | G6: =SUMIFS(Support!I:I,Support!B:B,'Roll up - Support'!B6,Support!E:E,'Roll up - Support'!C6) -> 122 | H6: =SUMIFS(Support!J:J,Support!B:B,'Roll up - Support'!B6,Support!E:E,'Roll up - Support'!C6) -> 0 | I6: =SUMIFS(Support!K:K,Support!B:B,'Roll up - Support'!B6,Support!E:E,'Roll up - Support'!C6) -> 122 | J6: =SUMIFS(Support!L:L,Support!B:B,'Roll up - Support'!B6,Support!E:E,'Roll up - Support'!C6) -> 0
B7: Castrol | C7: February | D7: =SUMIFS(Support!F:F,Support!B:B,'Roll up - Support'!B7,Support!E:E,'Roll up - Support'!C7) -> 60 | E7: =SUMIFS(Support!G:G,Support!B:B,'Roll up - Support'!B7,Support!E:E,'Roll up - Support'!C7) -> 0 | F7: =SUMIFS(Support!H:H,Support!B:B,'Roll up - Support'!B7,Support!E:E,'Roll up - Support'!C7) -> 0 | G7: =SUMIFS(Support!I:I,Support!B:B,'Roll up - Support'!B7,Support!E:E,'Roll up - Support'!C7) -> 106 | H7: =SUMIFS(Support!J:J,Support!B:B,'Roll up - Support'!B7,Support!E:E,'Roll up - Support'!C7) -> 0 | I7: =SUMIFS(Support!K:K,Support!B:B,'Roll up - Support'!B7,Support!E:E,'Roll up - Support'!C7) -> 106 | J7: =SUMIFS(Support!L:L,Support!B:B,'Roll up - Support'!B7,Support!E:E,'Roll up - Support'!C7) -> 0
D10: Total Incidents | E10: Number of major incidents (P1 & P2) | F10: Number of Aged Incidents (Over 30 days) | G10: Tasks Received | H10: Open Tasks | I10: Completed Tasks | J10: Aged Tasks (Over 30 days)
C11: January | D11: =SUMIF(C4:C7,C11,D4:D7) -> 182 | E11: =SUMIF(D4:D7,D11,E4:E7) -> 0 | F11: =SUMIF(E4:E7,E11,F4:F7) -> 0 | G11: =SUMIF(F4:F7,F11,G4:G7) -> 631 | H11: =SUMIF(G4:G7,G11,H4:H7) -> 0 | I11: =SUMIF(H4:H7,H11,I4:I7) -> 420 | J11: =SUMIF(I4:I7,I11,J4:J7) -> 0
C12: February | D12: =SUMIF(C5:C8,C12,D5:D8) -> 193 | E12: =SUMIF(D5:D8,D12,E5:E8) -> 0 | F12: =SUMIF(E5:E8,E12,F5:F8) -> 0 | G12: =SUMIF(F5:F8,F12,G5:G8) -> 439 | H12: =SUMIF(G5:G8,G12,H5:H8) -> 0 | I12: =SUMIF(H5:H8,H12,I5:I8) -> 228 | J12: =SUMIF(I5:I8,I12,J5:J8) -> 0
B16: Castrol | D16: Total Incidents | E16: Number of major incidents (P1 & P2) | F16: Number of Aged Incidents (Over 30 days)
C17: January | D17: 65 | E17: 0 | F17: 0
C18: February | D18: 60 | E18: 0 | F18: 0
D20: Tasks Received | E20: Open Tasks | F20: Completed Tasks | G20: Aged Tasks (Over 30 days)
C21: January | D21: 122 | E21: 0 | F21: 122 | G21: 0
C22: February | D22: 106 | E22: 0 | F22: 106 | G22: 0
D25: Total Incidents | E25: Number of major incidents (P1 & P2) | F25: Number of Aged Incidents (Over 30 days)
B26: Aviation | C26: January | D26: 115 | E26: 0 | F26: 0
C27: February | D27: 133 | E27: 0 | F27: 0
D28: Tasks Received | E28: Open Tasks | F28: Completed Tasks | G28: Aged Tasks (Over 30 days)
C29: January | D29: 163 | E29: 0 | F29: 163 | G29: 0
C30: February | D30: 59 | E30: 0 | F30: 59 | G30: 0

Sheet Roll up - Dev
D2: Velocity | F2: Quality
D3: % of Committed Product Backlog Item (PBI’s) (Ready) vs Delivered (Done) | E3: % of Story Points (SPs / Efforts) planned vs number of stories delivered | F3: Successful CI Changes (%) | G3: Number of Priority 3 and Priority 4 Incidents caused by CI Changes | H3: Automated test coverage (%)
B4: Aviation | C4: January | D4: =AVERAGEIFS(Development!F:F,Development!B:B,'Roll up - Dev'!B4,Development!E:E,'Roll up - Dev'!C4) -> 0.85641026 | E4: =AVERAGEIFS(Development!G:G,Development!B:B,'Roll up - Dev'!B4,Development!E:E,'Roll up - Dev'!C4) -> 0.75 | F4: =AVERAGEIFS(Development!H:H,Development!B:B,'Roll up - Dev'!B4,Development!E:E,'Roll up - Dev'!C4) -> 1 | G4: =SUMIFS(Development!I:I,Development!B:B,'Roll up - Dev'!B4,Development!D:D,'Roll up - Dev'!C4) -> 0 | H4: =AVERAGEIFS(Development!J:J,Development!B:B,'Roll up - Dev'!B4,Development!E:E,'Roll up - Dev'!C4) -> 0.81
B5: Aviation | C5: February | D5: =AVERAGEIFS(Development!F:F,Development!B:B,'Roll up - Dev'!B5,Development!E:E,'Roll up - Dev'!C5) -> 0.96 | E5: =AVERAGEIFS(Development!G:G,Development!B:B,'Roll up - Dev'!B5,Development!E:E,'Roll up - Dev'!C5) -> 0.56285 | F5: =AVERAGEIFS(Development!H:H,Development!B:B,'Roll up - Dev'!B5,Development!E:E,'Roll up - Dev'!C5) -> 1 | G5: =SUMIFS(Development!I:I,Development!B:B,'Roll up - Dev'!B5,Development!D:D,'Roll up - Dev'!C5) -> 0 | H5: =AVERAGEIFS(Development!J:J,Development!B:B,'Roll up - Dev'!B5,Development!E:E,'Roll up - Dev'!C5) -> 0.855
B6: Castrol | C6: January | D6: =AVERAGEIFS(Development!F:F,Development!B:B,'Roll up - Dev'!B6,Development!E:E,'Roll up - Dev'!C6) -> #DIV/0! | E6: =AVERAGEIFS(Development!G:G,Development!B:B,'Roll up - Dev'!B6,Development!E:E,'Roll up - Dev'!C6) -> #DIV/0! | F6: =AVERAGEIFS(Development!H:H,Development!B:B,'Roll up - Dev'!B6,Development!E:E,'Roll up - Dev'!C6) -> 1 | G6: =SUMIFS(Development!I:I,Development!B:B,'Roll up - Dev'!B6,Development!D:D,'Roll up - Dev'!C6) -> 0
B7: Castrol | C7: February | D7: =AVERAGEIFS(Development!F:F,Development!B:B,'Roll up - Dev'!B7,Development!E:E,'Roll up - Dev'!C7) -> #DIV/0! | E7: =AVERAGEIFS(Development!G:G,Development!B:B,'Roll up - Dev'!B7,Development!E:E,'Roll up - Dev'!C7) -> #DIV/0! | F7: =AVERAGEIFS(Development!H:H,Development!B:B,'Roll up - Dev'!B7,Development!E:E,'Roll up - Dev'!C7) -> 1 | G7: =SUMIFS(Development!I:I,Development!B:B,'Roll up - Dev'!B7,Development!D:D,'Roll up - Dev'!C7) -> 0
B8: CRM | C8: January | D8: =AVERAGEIFS(Development!F:F,Development!B:B,'Roll up - Dev'!B8,Development!E:E,'Roll up - Dev'!C8) -> 0.94833333 | E8: =AVERAGEIFS(Development!G:G,Development!B:B,'Roll up - Dev'!B8,Development!E:E,'Roll up - Dev'!C8) -> 0.925 | F8: =AVERAGEIFS(Development!H:H,Development!B:B,'Roll up - Dev'!B8,Development!E:E,'Roll up - Dev'!C8) -> 1 | G8: =SUMIFS(Development!I:I,Development!B:B,'Roll up - Dev'!B8,Development!D:D,'Roll up - Dev'!C8) -> 0 | H8: =AVERAGEIFS(Development!J:J,Development!B:B,'Roll up - Dev'!B8,Development!E:E,'Roll up - Dev'!C8) -> 0.875
B9: CRM | C9: February | D9: =AVERAGEIFS(Development!F:F,Development!B:B,'Roll up - Dev'!B9,Development!E:E,'Roll up - Dev'!C9) -> 0.925 | E9: =AVERAGEIFS(Development!G:G,Development!B:B,'Roll up - Dev'!B9,Development!E:E,'Roll up - Dev'!C9) -> 0.91166667 | F9: =AVERAGEIFS(Development!H:H,Development!B:B,'Roll up - Dev'!B9,Development!E:E,'Roll up - Dev'!C9) -> 1 | G9: =SUMIFS(Development!I:I,Development!B:B,'Roll up - Dev'!B9,Development!D:D,'Roll up - Dev'!C9) -> 0 | H9: =AVERAGEIFS(Development!J:J,Development!B:B,'Roll up - Dev'!B9,Development!E:E,'Roll up - Dev'!C9) -> 0.875
D12: % of Committed Product Backlog Item (PBI’s) (Ready) vs Delivered (Done) | E12: % of Story Points (SPs / Efforts) planned vs number of stories delivered | F12: Successful CI Changes (%) | G12: Number of Priority 3 and Priority 4 Incidents caused by CI Changes | H12: Automated test coverage (%)
C13: January | D13: =SUM(D4,D6,D8)/3 -> #DIV/0! | E13: =SUM(E4,E6,E8)/3 -> #DIV/0! | F13: =SUM(F4,F6,F8)/3 -> 1 | G13: =SUM(G4,G6,G8)/3 -> 0 | H13: =SUM(H4,H8)/2 -> 0.8425
C14: February | D14: =SUM(D5,D7,D9)/3 -> #DIV/0! | E14: =SUM(E5,E7,E9)/3 -> #DIV/0! | F14: =SUM(F5,F7,F9)/3 -> 1 | G14: =SUM(G5,G7,G9)/3 -> 0 | H14: =SUM(H5,H9)/2 -> 0.865
D20: % of Committed Product Backlog Item (PBI’s) (Ready) vs Delivered (Done) | E20: % of Story Points (SPs / Efforts) planned vs number of stories delivered
B21: CRM | C21: January | D21: 0.94833333 | E21: 0.925
B22: CRM | C22: February | D22: 0.925 | E22: 0.91166667
D28: Successful CI Changes (%) | E28: Number of Priority 3 and Priority 4 Incidents caused by CI Changes | F28: Automated test coverage (%)
C29: January | D29: 1 | E29: 0 | F29: 0.875
C30: February | D30: 1 | E30: 0 | F30: 0.875
B33: Castrol | D33: % of Committed Product Backlog Item (PBI’s) (Ready) vs Delivered (Done) | E33: % of Story Points (SPs / Efforts) planned vs number of stories delivered
C34: January | D34: 0.4 | E34: 1
C35: February | D35: 0.3 | E35: 0.89
D37: Successful CI Changes (%) | E37: Number of Priority 3 and Priority 4 Incidents caused by CI Changes | F37: Automated test coverage (%)
C38: January | D38: 1 | E38: 0
C39: February | D39: 1 | E39: 0
B44: Aviation | D44: % of Committed Product Backlog Item (PBI’s) (Ready) vs Delivered (Done) | E44: % of Story Points (SPs / Efforts) planned vs number of stories delivered
C45: January | D45: 0.85641026 | E45: 0.75
C46: February | D46: 0.96 | E46: 0.56285
D49: Successful CI Changes (%) | E49: Number of Priority 3 and Priority 4 Incidents caused by CI Changes | F49: Automated test coverage (%)
C50: January | D50: 1 | E50: 0 | F50: 0.81
C51: February | D51: 1 | E51: 0 | F51: 0.855
